Workbook

Sheet MIS Tracker
A1: Sr No. | B1: User Name | C1: App ID | D1: Customer Name | E1: Location | F1: Product | G1: Initiation Document (Sampled Documents) | H1: RCU Agency Name | I1: Login Month | J1: Received Date | K1: RCU Send | L1: TAT | M1: Report Status | N1: Report Comments | O1: Loan Amount applied | P1: Extra checks | Q1: ITR - @ 110 | R1: Financial - @ 450 | S1: PAN with Photo / PAN verification - @ 110 | T1: Passport @ 300 | U1: Bank Statement - @ 120 | V1: Form 16 / 26as -@ 110 | W1: GST - @ 350 | X1: Others (Noc Builder - Society / Demand Letter / SOA / Profile Check) Delhi & NCR - @ 150 | Y1: No.of Items (Total) | Z1: Total Amount | AA1: Sourcing Channel Name | AB1: Residence Address With PIN Code | AC1: Office Address With PIN Code | AD1: Mobile NO | AE1: Residence Type | AF1: Area : sq ft | AG1: Residence Locality | AH1: Residence Construction | AI1: Residence Exterior | AJ1: Residence Interior | AK1: Durables sighted at Residence- TV / AC / Fridge / Sofa / Music System | AL1: Vehicles sighted at Residence | AM1: Income group basis Residence visit | AN1: Resi Geo-Limit | AO1: Resi Neighbourhood check | AP1: Resi ownership status | AQ1: Vintage at same resi address & city | AR1: Alternate Contact No | AS1: Negative remarks for customer / customer’s family-member at same resi address | AT1: Remark | AU1: Office Locality type | AV1: Office Construction | AW1: Office Exterior | AX1: Office Interior | AY1: Nature of job / office work | AZ1: Vintage in same job / office work- Years / Months to be captured | BA1: No of employees sighted | BB1: Office ownership status | BC1: Vintage at same office address & city | BD1: Alternate Contact No | BE1: Office Neighbourhood check | BF1: Office Geo-Limit (Local / Outstation (If Outstation - Agency to specify distance)) | BG1: Negative remarks for customer / customer’s family-member / customer’s business associate at same office address | BH1: Detailed Office Visit Remarks
A2: 1 | B2: Krishna Murari | C2: DB202503135271763 | D2: Anuj Bairagee | E2: Delhi | F2: LAP | G2: 3. Banking 2. ITR 2. 26AS | H2: KPRM Management & Investigation Services | I2: 46104 | J2: 46104 | K2: 46105 | L2: =K2-J2 -> 1 | M2: Positive | N2: 1. BANKING - The given bank statement of Bank of India - A/C No. 712410110007261 - has been verified from the concerned bank and found that an account holder name is ANUJ BAIRAGEE, and the given all transactions got verified dated on 05/03/2026 - 30500/- CR (UPI), 03/02/2026 - 30500/- CR (UPI), 02/01/2026 - 90,000/- CR (UPI), which are matching with the bank record and found correct. Status - Positive. 2. BANKING - The given bank statement of HDFC Bank - A/C No. 50100699860467 - has been verified from the concerned bank and found that an account holder name is ANUJ BAIRAGEE, and the given all transactions got verified dated on 05/03/2026 - 30500/- CR (UPI), 03/02/2026 - 30500/- CR (UPI), 02/01/2026 - 90,000/- CR (UPI), which are matching with the bank record and found correct. Status - Positive. 3. BANKING - The given bank statement of HDFC Bank - A/C No. 50100257872234 - has been verified from the concerned bank and found that an account holder name is ANUJ BAIRAGI, and the given all transactions got verified dated on 30/01/2026 - 33,833/- CR (GENPACT), 31/12/2025 - 31,833/- CR (GENPACT), 27/11/2025 - 48,398/- CR (GENPACT), which are matching with the bank record and found correct. Status - Positive 4. ITR - (ANUJ BAIRAGEE) - We have verified an ITR of ANUJ BAIRAGEE, Pan no. DPIPB1239A, for AY-2024-25 and found that an ITR return has been filed with Ack No. 833609880210724, dated on 21-Jul-2024. Total income amount is Rs. 4,91,770/-. Status – Positive. 5. ITR : (ANUJ BAIRAGEE) - We have verified an ITR of ANUJ BAIRAGEE, Pan no. DPIPB1239A, for AY-2025-26 and found that an ITR return has been filed with Ack No. 203123930260625, dated on 26-Jun-2025. Total income amount is Rs. 5,95,700/-. Status – Positive. 6. 26AS : Anuj Bairagee - DPIPB1239A - 2025-26 - We have checked the 26AS record of ANUJ BAIRAGEE with PAN no. DPIPB1239A for 2025-26 at concerned department and found that employer name SPERIDIAN TECHNOLOGIES PRIVATE LIMITED Total income – 12,82,055/- Tax amount is 1,07,465/- Status – Positive 7. 26AS : ARUN BAIRAGI - DCPPB0708C - 2025-26 - We have checked the 26AS record of ARUN BAIRAGI with PAN no. DCPPB0708C for 2025-26 at concerned department and found that employer name GENPACT INDIA PRIVATE LIMITED Total income – 4,08,335/- Tax amount is 00/- Status – Positive | O2: 500000 | P2: NA | Q2: 3 | R2: 0 | S2: 0 | T2: 0 | U2: 2 | V2: 2 | W2: 0 | X2: 0 | Y2: =SUM(Q2:X2) -> 7 | Z2: =(Q2*110)+(R2*450)+(S2*110)+(T2*300)+(U2*120)+(V2*110)+(W2*350)+(X2*150) -> 790 | AA2: NA | AB2: NA | AC2: NA | AD2: NA | AE2: NA | AF2: NA | AG2: NA | AH2: NA | AI2: NA | AJ2: NA | AK2: NA | AL2: NA | AM2: NA | AN2: NA | AO2: NA | AP2: NA | AQ2: NA | AR2: NA | AS2: NA | AT2: NA | AU2: NA | AV2: NA | AW2: NA | AX2: NA | AY2: NA | AZ2: NA | BA2: NA | BB2: NA | BC2: NA | BD2: NA | BE2: NA | BF2: NA | BG2: NA | BH2: NA
A3: 2 | B3: Krishna Murari | C3: HLA202602165167940 | D3: Shiv Kumar | E3: Delhi | F3: Housing Loan | G3: 1. Banking 1. PWP | H3: KPRM Management & Investigation Services | I3: 46104 | J3: 46104 | K3: 46104 | L3: =K3-J3 -> 0 | M3: Positive | N3: 1. BANKING : (RAVINA) - The given bank statement of STATE BANK OF INDIAN - A/C No. 35774963835 - has been verified from the concerned bank and found that an account holder name is RAVINA, and the given transactions got verified dated on 16/03/2026 - 550/- DR (Closing Balance - 16864), 20/02/2026 - 158/- CR (Closing Balance - 21582), 03/02/2026 - 750,000/- CR (Closing Balance - 771707), which are matching with the bank record and found correct and AOD-17/05/2016. Status - Positive. 2. PAN WITH PHOTO : (RAVINA) - The Given PAN " AWFPR2519A " got checked and found that PAN holder Name- RAVINA and DOB- 24/05/1985 are correct as per the department record. Signature and Photo is also matching. Status – Positive. | O3: NA | P3: NA | Q3: 0 | R3: 0 | S3: 1 | T3: 0 | U3: 1 | V3: 0 | W3: 0 | X3: 0 | Y3: =SUM(Q3:X3) -> 2 | Z3: =(Q3*110)+(R3*450)+(S3*110)+(T3*300)+(U3*120)+(V3*110)+(W3*350)+(X3*150) -> 230 | AA3: NA | AB3: NA | AC3: NA | AD3: NA | AE3: NA | AF3: NA | AG3: NA | AH3: NA | AI3: NA | AJ3: NA | AK3: NA | AL3: NA | AM3: NA | AN3: NA | AO3: NA | AP3: NA | AQ3: NA | AR3: NA | AS3: NA | AT3: NA | AU3: NA | AV3: NA | AW3: NA | AX3: NA | AY3: NA | AZ3: NA | BA3: NA | BB3: NA | BC3: NA | BD3: NA | BE3: NA | BF3: NA | BG3: NA | BH3: NA

Sheet Report
A1: RCU / CPV Template: Jio Credit Ltd. | E1: Sr. No
A2: File No / Application No | B2: =VLOOKUP(E2,'MIS Tracker'!A:CJ,3,0) -> #N/A | E2: 87
A3: Customer Name | B3: =VLOOKUP(E2,'MIS Tracker'!A:CJ,4,0) -> #N/A
A4: Residence Address with Pincode | B4: =VLOOKUP(E2,'MIS Tracker'!A:CJ,27,0) -> #N/A
A5: Office Address with Pincode | B5: =VLOOKUP(E2,'MIS Tracker'!A:CJ,28,0) -> #N/A
A6: Mobile No | B6: =VLOOKUP(E2,'MIS Tracker'!A:CJ,29,0) -> #N/A
A7: Verification Location | B7: Delhi
A8: Product | B8: =VLOOKUP(E2,'MIS Tracker'!A:CJ,6,0) -> #N/A
A9: Loan amount required | B9: =VLOOKUP(E2,'MIS Tracker'!A:CJ,15,0) -> #N/A
A10: Sourcing Channel Name | B10: =VLOOKUP(E2,'MIS Tracker'!A:CJ,26,0) -> #N/A
A11: RCU / CPV Checks Required
A12: Resi Visit | B12: NA
A13: Office Visit | B13: NA
A14: Resi Office + Office Visit | B14: NA
A15: Documents to be sampled | B15: =VLOOKUP(E2,'MIS Tracker'!A:CJ,7,0) -> #N/A
A16: Verification Details
A17: Residence address verification remarks | B17: =VLOOKUP(E2,'MIS Tracker'!A:CJ,45,0) -> #N/A
A18: Residence Type | B18: =VLOOKUP(E2,'MIS Tracker'!A:CJ,30,0) -> #N/A
B19: =VLOOKUP(E2,'MIS Tracker'!A:CJ,31,0) -> #N/A
A20: Residence Locality | B20: =VLOOKUP(E2,'MIS Tracker'!A:CJ,32,0) -> #N/A
A21: Residence Construction | B21: =VLOOKUP(E2,'MIS Tracker'!A:CJ,33,0) -> #N/A
A22: Residence Exterior | B22: =VLOOKUP(E2,'MIS Tracker'!A:CJ,34,0) -> #N/A
A23: Residence Interior | B23: =VLOOKUP(E2,'MIS Tracker'!A:CJ,35,0) -> #N/A
A24: Durables sighted at Residence | B24: =VLOOKUP(E2,'MIS Tracker'!A:CJ,36,0) -> #N/A
A25: Vehicles sighted at Residence | B25: =VLOOKUP(E2,'MIS Tracker'!A:CJ,37,0) -> #N/A
A26: Income group basis Residence visit | B26: =VLOOKUP(E2,'MIS Tracker'!A:CJ,38,0) -> #N/A
A27: Resi Geo-Limit | B27: =VLOOKUP(E2,'MIS Tracker'!A:CJ,39,0) -> #N/A
A28: Resi Neighbourhood check | B28: =VLOOKUP(E2,'MIS Tracker'!A:CJ,40,0) -> #N/A
A29: Resi ownership status | B29: =VLOOKUP(E2,'MIS Tracker'!A:CJ,41,0) -> #N/A
A30: Vintage at same resi address & city | B30: Staying at same resi address : NA
B31: Staying in same city : NA
A32: Alternate Contact No | B32: =VLOOKUP(E2,'MIS Tracker'!A:CJ,43,0) -> #N/A
A33: Negative remarks for customer / customer’s family-member at same resi address | B33: =VLOOKUP(E2,'MIS Tracker'!A:CJ,44,0) -> #N/A
A34: Detailed Resi Visit Remarks | B34: =VLOOKUP(E2,'MIS Tracker'!A:CJ,45,0) -> #N/A
A35: Office address verification remarks | B35: =VLOOKUP(E2,'MIS Tracker'!A:CJ,59,0) -> #N/A
A36: Office Locality type | B36: =VLOOKUP(E2,'MIS Tracker'!A:CJ,46,0) -> #N/A
A37: Office Construction | B37: =VLOOKUP(E2,'MIS Tracker'!A:CJ,47,0) -> #N/A
A38: Office Exterior | B38: =VLOOKUP(E2,'MIS Tracker'!A:CJ,48,0) -> #N/A
A39: Office Interior | B39: =VLOOKUP(E2,'MIS Tracker'!A:CJ,49,0) -> #N/A
A40: Nature of job / office work | B40: =VLOOKUP(E2,'MIS Tracker'!A:CJ,50,0) -> #N/A
...
